Workbook
Name AccessoryCircuits: [2]ExerciseInventory!$BX$3:$BX$7
Name AccessoryCircuits: [1]ExerciseInventory!$BX$3:$BX$7
Name AccessoryTriplets: [2]ExerciseInventory!$W$4:$W$222
Name AccessoryTriplets: [1]ExerciseInventory!$W$4:$W$225
Name athletenames: [2]ControlPanel!$AS$6:$AS$29
Name athletenames: [1]ControlPanel!$AS$6:$AS$29
Name athletes: [2]ControlPanel!$AS$6:$AS$29
Name athletes: [1]ControlPanel!$AS$6:$AS$29
Name Categories: [2]ExerciseInventory!$A$2:$A$14
Name Categories: [1]ExerciseInventory!$A$2:$A$14
Name Core: [1]ExerciseInventory!$H$3:$H$382
Name Correctives: [2]ExerciseInventory!$Q$3:$Q$595
Name Correctives: [1]ExerciseInventory!$Q$3:$Q$595
Name CrazyCore: [2]ExerciseInventory!$H$237:$H$254
Name CrazyCore: [1]ExerciseInventory!$H$237:$H$254
Name CxReps: [2]ExerciseInventory!$BE$4:$BE$26
Name CxReps: [1]ExerciseInventory!$BE$4:$BE$26
Name Eqpt: [2]ExerciseInventory!$BF$4:$BF$25
Name Eqpt: [1]ExerciseInventory!$BF$4:$BF$25
Name ExerciseOrder: [2]ExerciseInventory!$BB$4:$BB$29
Name ExerciseOrder: [1]ExerciseInventory!$BB$4:$BB$29
Name LiftTracking: [2]ExerciseInventory!$AQ$3:$AQ$45
Name LiftTracking: [1]ExerciseInventory!$AQ$3:$AQ$45
Name ListSetRepSchemes: [2]ControlPanel!$A$5:$A$282
Name ListSetRepSchemes: [1]ControlPanel!$A$5:$A$282
Name LoadCategories: [2]ExerciseInventory!$A$15:$A$20
Name LoadCategories: [1]ExerciseInventory!$A$15:$A$20
Name MobTracking: [2]ExerciseInventory!$AR$3:$AR$45
Name MobTracking: [1]ExerciseInventory!$AR$3:$AR$45
Name ProgramObjectives: [2]ControlPanel!$AM$46:$AM$57
Name ProgramObjectives: [1]ControlPanel!$AM$46:$AM$57
Name skiCamps: [2]ControlPanel!$BI$28:$BI$36
Name skiCamps: [1]ControlPanel!$BI$28:$BI$36
Name TableAccessoryTriplets: [2]ExerciseInventory!$W$4:$AJ$222
Name TableAccessoryTriplets: [1]ExerciseInventory!$W$4:$AJ$225
Name TableSetRepSchemes: [2]ControlPanel!$A$5:$AJ$282
Name TableSetRepSchemes: [1]ControlPanel!$A$5:$AJ$282
Name Tempo: [2]ExerciseInventory!$BC$4:$BC$39
Name Tempo: [1]ExerciseInventory!$BC$4:$BC$39
Name TrainingPhases: [2]ControlPanel!$AM$2:$AM$71
Name TrainingPhases: [1]ControlPanel!$AM$2:$AM$71
Name VBTExercises: [2]ExerciseInventory!$BX$79:$BX$86
Name VBTExercises: [1]ExerciseInventory!$BX$79:$BX$86
Name WarmUps: [2]ExerciseInventory!$AT$29:$AT$48
Name WarmUps: [1]ExerciseInventory!$AT$29:$AT$48

Sheet acl_ytp
A2: ACLR - YTP
A3: Exercise Planning | C3: Week -8 | J3: Week -7 | Q3: Week -6 | X3: Week -5 | AE3: Week -4 | AL3: Week -3 | AS3: Week -2 | AZ3: Week -1 | BG3: Week 0 | BN3: Week 1 | BU3: Week 2 | CB3: Week 3 | CI3: Week 4 | CP3: Week 5 | CW3: Week 6 | DD3: Week 7 | DK3: Week 8 | DR3: Week 9 | DY3: Week 10 | EF3: Week 11 | EM3: Week 12 | ET3: Week 13 | FA3: Week 14 | FH3: Week 15 | FO3: Week 16 | FV3: Week 17 | GC3: Week 18 | GJ3: Week 19 | GQ3: Week 20 | GX3: Week 21 | HE3: Week 22 | HL3: Week 23 | HS3: Week 24 | HZ3: Week 25 | IG3: Week 26 | IN3: Week 27 | IU3: Week 28 | JB3: Week 29 | JI3: Week 30 | JP3: Week 31 | JW3: Week 32 | KD3: Week 33 | KK3: Week 34 | KR3: Week 35 | KY3: Week 36 | LF3: Week 37 | LM3: Week 38 | LT3: Week 39 | MA3: Week 40 | MH3: Week 41 | MO3: Week 42 | MV3: Week 43 | NC3: Week 44 | NJ3: Week 45 | NQ3: Week 46 | NX3: Week 47 | OE3: Week 48 | OL3: Week 49 | OS3: Week 50 | OZ3: Week 51 | PG3: Week 52
A10: Move/Mobilize | DL10: 1 time through full circuit
BU11: A | BV11: Manual Patella Mob | CA11: 10 | DK11: A | DL11: Cat Camel | DQ11: 6 | DR11: A | DS11: Cat Camel | DX11: 6 | DY11: A | DZ11: Cat Camel | EE11: 6 | EF11: A | EG11: Cat Camel | EL11: 6 | EM11: A | EN11: Cat Camel | ES11: 6 | ET11: A | EU11: Cat Camel | EZ11: 6
BU12: B | BV12: Long Duration Passive Leg Ext. | CA12: 5m | DK12: B | DL12: Side to Side Knee Rolls | DQ12: 8 | DR12: B | DS12: Side to Side Knee Rolls | DX12: 8 | DY12: B | DZ12: Side to Side Knee Rolls | EE12: 8 | EF12: B | EG12: Side to Side Knee Rolls | EL12: 8 | EM12: B | EN12: Side to Side Knee Rolls | ES12: 8 | ET12: B | EU12: Side to Side Knee Rolls | EZ12: 8
BU13: C | BV13: Heel Slides | CA13: 20 | DK13: C | DL13: Heel Sldies | DQ13: 10 | DR13: C | DS13: Heel Sldies | DX13: 10 | DY13: C | DZ13: Heel Sldies | EE13: 10 | EF13: C | EG13: Heel Sldies | EL13: 10 | EM13: C | EN13: Heel Sldies | ES13: 10 | ET13: C | EU13: Heel Sldies | EZ13: 10
BU14: D | BV14: Seated SL Ham Stretch | CA14: 30s | DK14: D | DL14: Leg Swings - small ROM all directions | DQ14: 8 | DR14: D | DS14: Leg Swings - small ROM all directions | DX14: 8 | DY14: D | DZ14: Leg Swings - small ROM all directions | EE14: 8 | EF14: D | EG14: Leg Swings - small ROM all directions | EL14: 8 | EM14: D | EN14: Leg Swings - small ROM all directions | ES14: 8 | ET14: D | EU14: Leg Swings - small ROM all directions | EZ14: 8
BU15: E | BV15: Seated Calf Stretch | CA15: 30s | DK15: E | DL15: Air Squat | DQ15: 8 | DR15: E | DS15: Air Squat w/ dowel | DX15: 8 | DY15: E | DZ15: Air Squat w/ dowel | EE15: 8 | EF15: E | EG15: 6" Squat from MB | EL15: 8 | EM15: E | EN15: 6" Squat from MB | ES15: 8 | ET15: E | EU15: 6" Squat from MB | EZ15: 8
DK16: F | DL16: SLR RDL + rot. w/ support | DQ16: 4 | DR16: F | DS16: SLR RDL + rot. w/ support | DX16: 4 | DY16: F | DZ16: SLR RDL + rot. w/ support | EE16: 4 | EF16: F | EG16: SLR RDL + rot. w/ support | EL16: 4 | EM16: F | EN16: SLR RDL + rot. w/ support | ES16: 4 | ET16: F | EU16: SLR RDL + rot. w/ support | EZ16: 4
DK17: G | DL17: Split Squats | DQ17: 8 | DR17: G | DS17: Split Squats | DX17: 8 | DY17: G | DZ17: Split Squats | EE17: 8 | EF17: G | EG17: Split Squats | EL17: 8 | EM17: G | EN17: Split Squats | ES17: 8 | ET17: G | EU17: Split Squats | EZ17: 8
DK18: H | DL18: Alt Hip 90-90s | DQ18: 8 | DR18: H | DS18: Alt Hip 90-90s | DX18: 8 | DY18: H | DZ18: Alt Hip 90-90s | EE18: 8 | EF18: H | EG18: Alt Hip 90-90s | EL18: 8 | EM18: H | EN18: Alt Hip 90-90s | ES18: 8 | ET18: H | EU18: Alt Hip 90-90s | EZ18: 8
DK19: I | DL19: Kneeling sit back on Heels | DP19: 5 ISO | DQ19: 6 | DR19: I | DS19: Kneeling sit back on Heels | DW19: 5 ISO | DX19: 6 | DY19: I | DZ19: Kneeling sit back on Heels | ED19: 5 ISO | EE19: 6 | EF19: I | EG19: Kneeling sit back on Heels | EK19: 5 ISO | EL19: 6 | EM19: I | EN19: Kneeling sit back on Heels | ER19: 5 ISO | ES19: 6 | ET19: I | EU19: Kneeling sit back on Heels | EY19: 5 ISO | EZ19: 6
EF20: J | EG20: ISO SL Extension | EK20: 30 ISO | EL20: 3 | EM20: J | EN20: ISO SL Extension | ER20: 30 ISO | ES20: 4 | ET20: J | EU20: ISO SL Extension | EY20: 30 ISO | EZ20: 5
A21: Activation | DK21: 3 supersets, do only 2 each day | DS21: Exercise | DW21: Tempo | DX21: 2x
BU22: A | BV22: Quad Squeeze - Half Roller | CA22: 10 | DK22: 1A | DL22: Standing TKE w/ band | DP22: 5 ISO | DQ22: 5 | DR22: 1A | DS22: Standing TKE w/ band | DW22: 5 ISO | DX22: 6 | DY22: 1A | DZ22: Standing TKE w/ band | ED22: 5 ISO | EE22: 6 | EF22: 1A | EG22: SL 3-way Step Down, band TKE | EL22: 3 | EM22: 1A | EN22: SL 3-way Step Down, band TKE | ES22: 4 | ET22: 1A | EU22: SL 3-way Step Down, band TKE | EZ22: 5
BU23: B | BV23: Supine ADD Ball Squeeze 90º | BZ23: 10 ISO | CA23: 6 | DK23: 1B | DL23: Standing Hip flexion w/ mb | DP23: 2 ISO | DQ23: 5 | DR23: 1B | DS23: Standing Hip flexion w/ mb | DW23: 2 ISO | DX23: 6 | DY23: 1B | DZ23: Standing Hip flexion w/ mb + MB OH | ED23: 1 ISO | EE23: 6 | EF23: 1B | EG23: Knee Side Plank + Opp Straight Leg Raise | EL23: 10 | EM23: 1B | EN23: Knee Side Plank + Opp Straight Leg Raise | ES23: 11 | ET23: 1B | EU23: Knee Side Plank + Opp Straight Leg Raise | EZ23: 12
BU24: C | BV24: Side Lying Clamshell | BZ24: 2 ISO | CA24: 10 | DK24: 1C | DL24: Backwards Treadmill Walking | DQ24: 0.083333333 | DR24: 1C | DS24: Backwards Treadmill Walking | DX24: 0.10416667 | DY24: 1C | DZ24: Backwards Treadmill Walking | EE24: 0.125 | EF24: 1C | EG24: Add. V-Ball Squeeze + crunches | EL24: 15 | EM24: 1C | EN24: Add. V-Ball Squeeze + crunches | ES24: 20 | ET24: 1C | EU24: Add. V-Ball Squeeze + rot. crunches | EZ24: 20
BU25: D | BV25: DL Heel Raise | CA25: 10 | DK25: 2A | DL25: SL 3-way Step down | DQ25: 4 | DR25: 2A | DS25: SL 3-way Step down | DX25: 5 | DY25: 2A | DZ25: SL 3-way Step down | EE25: 6 | EF25: 2A | EG25: ISO Decline Squat + Lateral Reaches | EL25: :40 | EM25: 2A | EN25: ISO Decline Squat + Lateral Reaches | ES25: :50 | ET25: 2A | EU25: ISO Decline Squat + Lateral Reaches | EZ25: :60
BU26: E | BV26: SL Balance | CA26: 30s | DK26: 2B | DL26: Lateral MH Step Overs | DQ26: 8 | DR26: 2B | DS26: Lateral MH Step Overs | DX26: 10 | DY26: 2B | DZ26: Lateral Hurdle Step Over/Under | EE26: 10 | EF26: 2B | EG26: Knee Copenhagen | EL26: :20 | EM26: 2B | EN26: Knee Copenhagen | ES26: :25 | ET26: 2B | EU26: Knee Copenhagen | EZ26: :30
DK27: 2C | DL27: Bird Dog Leg Ext | DP27: 2 ISO | DQ27: 6 | DR27: 2C | DS27: Bird Dog Leg Ext | DW27: 2 ISO | DX27: 8 | DY27: 2C | DZ27: Bird Dogs | ED27: 2 ISO | EE27: 6 | EF27: 2C | EG27: Bird Dogs | EK27: 2 ISO | EL27: 6 | EM27: 2C | EN27: Bird Dogs | ER27: 2 ISO | ES27: 8 | ET27: 2C | EU27: Bird Dogs (bear crawl pos) | EY27: 2 ISO | EZ27: 6
DK28: 3A | DL28: SL Wall Sit | DP28: 10 ISO | DQ28: 3 | DR28: 3A | DS28: SL Wall Sit | DW28: 10 ISO | DX28: 4 | DY28: 3A | DZ28: SL Decline Wall Sit | ED28: 15 ISO | EE28: 2 | EF28: 3A | EG28: Split Squat w/ band ADD | EL28: 8 | EM28: 3A | EN28: Split Squat w/ band ADD | ES28: 10 | ET28: 3A | EU28: Split Squat w/ band ADD | EZ28: 12
DK29: 3B | DL29: Standing Hip ADD w/ cable | DQ29: 10 | DR29: 3B | DS29: Standing Hip ADD w/ cable | DX29: 10 | DY29: 3B | DZ29: Standing Hip ADD w/ cable | EE29: 10 | EF29: 3B | EG29: Standing Hip Flex. Mini band | EK29: 5 ISO | EL29: 3 | EM29: 3B | EN29: Standing Hip Flex. Mini band | ER29: 5 ISO | ES29: 4 | ET29: 3B | EU29: Standing Hip Flex. Mini band | EY29: 5 ISO | EZ29: 5
DK30: 3C | DL30: Alt. Dead Bug Leg Ext (oh band) | DQ30: 8 | DR30: 3C | DS30: Alt. Dead Bug Leg Ext (oh band) | DX30: 10 | DY30: 3C | DZ30: Alt. Dead Bug Leg Ext (oh band) | EE30: 10 | EF30: 3C | EG30: Alt Dead bugs w/ band OH | EL30: 7 | EM30: 3C | EN30: Alt Dead bugs w/ band OH | ES30: 8 | ET30: 3C | EU30: Alt Dead bugs w/ band OH, miniband feet | EZ30: 7
A32: Preparation 1 | DQ32: 2x | DX32: 2x | EE32: 2x | EL32: 2x | ES32: 2x | EZ32: 2x
DK33: 1A | DL33: DL Squats - Bosu (flat up) | DQ33: 8 | DR33: 1A | DS33: Squats - Bosu (flat up) | DX33: 10 | DY33: 1A | DZ33: ISO Decline Squat + Lateral Reaches | EE33: :30 | EF33: 1A | EG33: Y Balance | EL33: 3 | EM33: 1A | EN33: Y Balance | ES33: 4 | ET33: 1A | EU33: Y Balance | EZ33: 5
DK34: 1B | DL34: SL Balance | DQ34: 30s | DR34: 1B | DS34: Square Balance Board L-R | DX34: 30s | DY34: 1B | DZ34: Alt. MB Rot Pass (bosu, face wall) | EE34: 8 | EF34: 1B | EG34: SL Balance - Mini Tramp | EL34: :20 | EM34: 1B | EN34: SL Balance - Mini Tramp | ES34: :25 | ET34: 1B | EU34: SL Balance - Mini Tramp | EZ34: :30
DK35: 1C | DL35: ISO Lunge - Eyes closed | DQ35: 20s | DR35: 1C | DS35: SL Balance - Eyes cloed | DX35: 20s | DY35: 1C | DZ35: DL Half Squats - Eyes closed | EE35: 8 | EF35: 1C | EG35: DL Balance Board (AP) | EL35: :30 | EM35: 1C | EN35: DL Balance Board (AP) | ES35: :30 | ET35: 1C | EU35: DL Balance Board (AP) | EZ35: :30
DK36: 2A | DL36: MB Slam - 50% effort | DQ36: 6 | DR36: 2A | DS36: MB Slam - 70% effort | DX36: 6 | DY36: 2A | DZ36: MB Slam - 80% effort | EE36: 6 | EM36: 1D | EN36: DL Balance Board (ML) | ES36: :30 | ET36: 1D | EU36: DL Balance Board (ML) | EZ36: :30
DK37: 2B | DL37: Alt. MB Rot Pass - facing wall | DQ37: 6 | DR37: 2B | DS37: Alt. MB Rot Pass - facing wall | DX37: 6 | DY37: 2B | DZ37: Lateral Rot. Pass - 50% effort | EE37: 3
DK38: 2C | DL38: 1/2 Squat + MB Chest Pass | DQ38: 6 | DR38: 2C | DS38: 1/2 Squat + MB Chest Pass | DX38: 6 | DY38: 2C | DZ38: 1/2 Squat + Upward Granny Toss | EE38: 5
DK39: 3A | DR39: 3A | DY39: 3A
DK40: 3B | DR40: 3B | DY40: 3B
DK41: 3C | DR41: 3C | DY41: 3C
A43: Preparation 2 | EF43: 2 supersets, do only 1 each day | EM43: 2 supersets, do only 1 each day | ET43: 2 supersets, do only 1 each day
EF44: 1A | EG44: A March / Low Slow Back Pedal | EL44: 20m | EM44: 1A | EN44: A March / Low Slow Back Pedal | ES44: 20m | ET44: 1A | EU44: A March / Low Slow Back Pedal | EZ44: 20m
EF45: 1B | EG45: Butt Kicks / Walk back knee hug | EL45: 20m | EM45: 1B | EN45: Butt Kicks / Walk back knee hug | ES45: 20m | ET45: 1B | EU45: Butt Kicks / Walk back knee hug | EZ45: 20m
EF46: 1C | EG46: Lateral A March - Tall Hurdles | EL46: 8 | EM46: 1C | EN46: Lateral A March - Tall Hurdles | ES46: 8 | ET46: 1C | EU46: Lateral A March - Tall Hurdles | EZ46: 8
EF47: 2A | EG47: Staggered Stance MB Slam | EK47: 0.5 | EL47: 4 | EM47: 2A | EN47: Staggered Stance MB Slam | ER47: 0.6 | ES47: 4 | ET47: 2A | EU47: Staggered Stance MB Slam | EY47: 0.7 | EZ47: 4
EF48: 2B | EG48: Lateral Rot. Pass - small step | EL48: 4 | EM48: 2B | EN48: Lateral Rot. Pass - small step | ES48: 5 | ET48: 2B | EU48: Lateral Rot. Pass - small step | EZ48: 6
EF49: 2C | EG49: 1/2 Squat + Upward Granny Toss | EL49: 4 | EM49: 2C | EN49: 1/2 Squat + Upward Granny Toss | ES49: 5 | ET49: 2C | EU49: 1/2 Squat + Upward Granny Toss | EZ49: 6
...

Sheet Checklist
B1: -8 | C1: -7 | D1: -6 | E1: -5 | F1: -4 | G1: -3 | H1: -2 | I1: -1 | J1: 0 | K1: 1 | L1: 2 | M1: 3 | N1: 4 | O1: 5 | P1: 6 | Q1: 7 | R1: 8 | S1: 9 | T1: 10 | U1: 11 | V1: 12 | W1: 13 | X1: 14 | Y1: 15 | Z1: 16 | AA1: 17 | AB1: 18 | AC1: 19 | AD1: 20 | AE1: 21 | AF1: 22 | AG1: 23 | AH1: 24 | AI1: 25 | AJ1: 26 | AK1: 27 | AL1: 28 | AM1: 29 | AN1: 30 | AO1: 31 | AP1: 32 | AQ1: 33 | AR1: 34 | AS1: 35 | AT1: 36 | AU1: 37 | AV1: 38 | AW1: 39 | AX1: 40 | AY1: 41 | AZ1: 42 | BA1: 43 | BB1: 44 | BC1: 45 | BD1: 46 | BE1: 47 | BF1: 48 | BG1: 49 | BH1: 50 | BI1: 51 | BJ1: 52
A2: Move/Mobilize | B2: 1 | C2: 1 | D2: 1 | E2: 1 | F2: 1 | G2: 1 | H2: 1 | I2: 1 | J2: 1 | K2: 1 | L2: 1 | M2: 1 | N2: 1 | O2: 1 | P2: 1 | Q2: 1 | R2: 1 | S2: 1 | T2: 1 | U2: 1 | V2: 1 | W2: 1 | X2: 1 | Y2: 1 | Z2: 1 | AA2: 1 | AB2: 1 | AC2: 1 | AD2: 1 | AE2: 1 | AF2: 1 | AG2: 1 | AH2: 1 | AI2: 1 | AJ2: 1 | AK2: 1 | AL2: 1 | AM2: 1 | AN2: 1 | AO2: 1 | AP2: 1 | AQ2: 1 | AR2: 1 | AS2: 1 | AT2: 1 | AU2: 1 | AV2: 1 | AW2: 1 | AX2: 1 | AY2: 1 | AZ2: 1 | BA2: 1 | BB2: 1 | BC2: 1 | BD2: 1 | BE2: 1 | BF2: 1 | BG2: 1 | BH2: 1 | BI2: 1 | BJ2: 1
A3: Activation | D3: 1 | E3: 1 | F3: 1 | G3: 1 | H3: 1 | I3: 1 | M3: 1 | N3: 1 | O3: 1 | P3: 1 | Q3: 1 | R3: 1
A4: Potentiation | R4: 1
A5: Lower 1 | R5: 1 | S5: 1 | T5: 1 | U5: 1 | V5: 1 | W5: 1 | X5: 1 | Y5: 1 | Z5: 1 | AA5: 1 | AB5: 1 | AC5: 1 | AD5: 1 | AE5: 1 | AF5: 1 | AG5: 1 | AH5: 1 | AI5: 1 | AJ5: 1 | AK5: 1 | AL5: 1 | AM5: 1 | AN5: 1 | AO5: 1 | AP5: 1 | AQ5: 1 | AR5: 1 | AS5: 1 | AT5: 1 | AU5: 1 | AV5: 1 | AW5: 1 | AX5: 1 | AY5: 1 | AZ5: 1 | BA5: 1 | BB5: 1 | BC5: 1 | BD5: 1 | BE5: 1 | BF5: 1 | BG5: 1 | BH5: 1 | BI5: 1 | BJ5: 1
A6: Lower 2 | R6: 1 | S6: 1 | T6: 1 | U6: 1 | V6: 1 | W6: 1 | X6: 1 | Y6: 1 | Z6: 1 | AA6: 1 | AB6: 1 | AC6: 1 | AD6: 1 | AE6: 1 | AF6: 1 | AG6: 1 | AH6: 1 | AI6: 1 | AJ6: 1 | AK6: 1 | AL6: 1 | AM6: 1 | AN6: 1 | AO6: 1 | AP6: 1 | AQ6: 1 | AR6: 1 | AS6: 1 | AT6: 1 | AU6: 1 | AV6: 1 | AW6: 1 | AX6: 1 | AY6: 1 | AZ6: 1 | BA6: 1 | BB6: 1 | BC6: 1 | BD6: 1 | BE6: 1 | BF6: 1 | BG6: 1 | BH6: 1 | BI6: 1 | BJ6: 1
A7: Lower 3 | R7: 1 | S7: 1 | T7: 1 | U7: 1 | V7: 1 | W7: 1 | X7: 1 | Y7: 1 | Z7: 1 | AA7: 1 | AB7: 1 | AC7: 1 | AD7: 1 | AE7: 1 | AF7: 1 | AG7: 1 | AH7: 1 | AI7: 1 | AJ7: 1 | AK7: 1 | AL7: 1 | AM7: 1 | AN7: 1 | AO7: 1 | AP7: 1 | AQ7: 1 | AR7: 1 | AS7: 1 | AT7: 1 | AU7: 1 | AV7: 1 | AW7: 1 | AX7: 1 | AY7: 1 | AZ7: 1 | BA7: 1 | BB7: 1 | BC7: 1 | BD7: 1 | BE7: 1 | BF7: 1 | BG7: 1 | BH7: 1 | BI7: 1 | BJ7: 1
A8: Lower 4
A9: Non ACLR 1 | B9: 1 | C9: 1 | D9: 1 | E9: 1 | F9: 1 | G9: 1 | H9: 1 | I9: 1 | L9: 1 | M9: 1 | N9: 1 | O9: 1 | P9: 1 | Q9: 1 | R9: 1 | S9: 1 | T9: 1 | U9: 1 | V9: 1 | W9: 1 | X9: 1 | Y9: 1 | Z9: 1 | AA9: 1 | AB9: 1 | AC9: 1 | AD9: 1 | AE9: 1 | AF9: 1 | AG9: 1 | AH9: 1 | AI9: 1
A10: Non ACLR 2 | B10: 1 | C10: 1 | D10: 1 | E10: 1 | F10: 1 | G10: 1 | H10: 1 | I10: 1 | L10: 1 | M10: 1 | N10: 1 | O10: 1 | P10: 1 | Q10: 1 | R10: 1 | S10: 1 | T10: 1 | U10: 1 | V10: 1 | W10: 1 | X10: 1 | Y10: 1 | Z10: 1 | AA10: 1 | AB10: 1 | AC10: 1 | AD10: 1 | AE10: 1 | AF10: 1 | AG10: 1 | AH10: 1 | AI10: 1
A11: Non ACLR 3
A12: Hydro 1 | M12: 1 | N12: 1 | O12: 1 | P12: 1 | Q12: 1 | R12: 1 | S12: 1 | T12: 1 | U12: 1 | V12: 1 | W12: 1
A13: Hydro 2 | M13: 1 | N13: 1 | O13: 1 | P13: 1 | Q13: 1 | R13: 1 | S13: 1 | T13: 1 | U13: 1 | V13: 1 | W13: 1
A14: BFR 1 | E14: 1 | F14: 1 | G14: 1 | H14: 1 | I14: 1 | L14: 1 | M14: 1 | N14: 1 | O14: 1 | P14: 1 | Q14: 1 | R14: 1 | S14: 1 | T14: 1 | U14: 1 | V14: 1 | W14: 1 | X14: 1 | Y14: 1
A15: BFR 2 | E15: 1 | F15: 1 | G15: 1 | H15: 1 | I15: 1 | L15: 1 | M15: 1 | N15: 1 | O15: 1 | P15: 1 | Q15: 1 | R15: 1 | S15: 1 | T15: 1 | U15: 1 | V15: 1 | W15: 1 | X15: 1 | Y15: 1
A16: PLYO 1 | AA16: 1 | AB16: 1 | AC16: 1 | AD16: 1 | AE16: 1 | AF16: 1 | AG16: 1 | AH16: 1 | AI16: 1 | AJ16: 1 | AK16: 1 | AL16: 1 | AM16: 1 | AN16: 1 | AO16: 1 | AP16: 1 | AQ16: 1 | AR16: 1 | AS16: 1 | AT16: 1 | AU16: 1 | AV16: 1 | AW16: 1 | AX16: 1 | AY16: 1 | AZ16: 1 | BA16: 1 | BB16: 1 | BC16: 1 | BD16: 1 | BE16: 1 | BF16: 1 | BG16: 1 | BH16: 1 | BI16: 1 | BJ16: 1
A17: PLYO 2 | AA17: 1 | AB17: 1 | AC17: 1 | AD17: 1 | AE17: 1 | AF17: 1 | AG17: 1 | AH17: 1 | AI17: 1 | AJ17: 1 | AK17: 1 | AL17: 1 | AM17: 1 | AN17: 1 | AO17: 1 | AP17: 1 | AQ17: 1 | AR17: 1 | AS17: 1 | AT17: 1 | AU17: 1 | AV17: 1 | AW17: 1 | AX17: 1 | AY17: 1 | AZ17: 1 | BA17: 1 | BB17: 1 | BC17: 1 | BD17: 1 | BE17: 1 | BF17: 1 | BG17: 1 | BH17: 1 | BI17: 1 | BJ17: 1
A18: PLYO 3 | AA18: 1 | AB18: 1 | AC18: 1 | AD18: 1 | AE18: 1 | AF18: 1 | AG18: 1 | AH18: 1 | AI18: 1 | AJ18: 1 | AK18: 1 | AL18: 1 | AM18: 1 | AN18: 1 | AO18: 1 | AP18: 1 | AQ18: 1 | AR18: 1 | AS18: 1 | AT18: 1 | AU18: 1 | AV18: 1 | AW18: 1 | AX18: 1 | AY18: 1 | AZ18: 1 | BA18: 1 | BB18: 1 | BC18: 1 | BD18: 1 | BE18: 1 | BF18: 1 | BG18: 1 | BH18: 1 | BI18: 1 | BJ18: 1
A19: SAQ 1 | AE19: 1 | AF19: 1 | AG19: 1 | AH19: 1 | AI19: 1 | AJ19: 1 | AK19: 1 | AL19: 1 | AM19: 1 | AN19: 1 | AO19: 1 | AP19: 1 | AQ19: 1 | AR19: 1 | AS19: 1 | AT19: 1 | AU19: 1 | AV19: 1 | AW19: 1 | AX19: 1 | AY19: 1 | AZ19: 1 | BA19: 1 | BB19: 1 | BC19: 1 | BD19: 1 | BE19: 1 | BF19: 1 | BG19: 1 | BH19: 1 | BI19: 1 | BJ19: 1
A20: SAQ 2 | AE20: 1 | AF20: 1 | AG20: 1 | AH20: 1 | AI20: 1 | AJ20: 1 | AK20: 1 | AL20: 1 | AM20: 1 | AN20: 1 | AO20: 1 | AP20: 1 | AQ20: 1 | AR20: 1 | AS20: 1 | AT20: 1 | AU20: 1 | AV20: 1 | AW20: 1 | AX20: 1 | AY20: 1 | AZ20: 1 | BA20: 1 | BB20: 1 | BC20: 1 | BD20: 1 | BE20: 1 | BF20: 1 | BG20: 1 | BH20: 1 | BI20: 1 | BJ20: 1
A21: ES1 | N21: 1 | O21: 1 | P21: 1 | Q21: 1 | R21: 1 | S21: 1 | T21: 1 | U21: 1 | V21: 1 | W21: 1 | X21: 1 | Y21: 1 | Z21: 1 | AA21: 1 | AB21: 1 | AC21: 1 | AD21: 1 | AE21: 1 | AF21: 1 | AG21: 1 | AH21: 1 | AI21: 1 | AJ21: 1 | AK21: 1 | AL21: 1 | AM21: 1 | AN21: 1 | AO21: 1 | AP21: 1 | AQ21: 1 | AR21: 1 | AS21: 1 | AT21: 1 | AU21: 1 | AV21: 1 | AW21: 1 | AX21: 1 | AY21: 1 | AZ21: 1 | BA21: 1 | BB21: 1 | BC21: 1 | BD21: 1 | BE21: 1 | BF21: 1 | BG21: 1 | BH21: 1 | BI21: 1 | BJ21: 1
A22: ES2 | N22: 1 | O22: 1 | P22: 1 | Q22: 1 | R22: 1 | S22: 1 | T22: 1 | U22: 1 | V22: 1 | W22: 1 | X22: 1 | Y22: 1 | Z22: 1 | AA22: 1 | AB22: 1 | AC22: 1 | AD22: 1 | AE22: 1 | AF22: 1 | AG22: 1 | AH22: 1 | AI22: 1 | AJ22: 1 | AK22: 1 | AL22: 1 | AM22: 1 | AN22: 1 | AO22: 1 | AP22: 1 | AQ22: 1 | AR22: 1 | AS22: 1 | AT22: 1 | AU22: 1 | AV22: 1 | AW22: 1 | AX22: 1 | AY22: 1 | AZ22: 1 | BA22: 1 | BB22: 1 | BC22: 1 | BD22: 1 | BE22: 1 | BF22: 1 | BG22: 1 | BH22: 1 | BI22: 1 | BJ22: 1
A23: ES3
A24: Accessory 1
A25: Accessory 2
A26: Acc. Triplet 1
A27: Acc. Triplet 2
A28: Acc. Triplet 3
A29: Acc. Triplet 4
A30: Accessory 5
A31: Accessory 6
A32: Accessory 7
A33: Accessory 8

Sheet 1
A2: Program Objectives | D2: Program Rationale | X2: Pre/During-Programming Notes | BF2: Next Steps
A3: 1 | BF3: 1
A4: 2 | BF4: 2
A5: 3 | BF5: 3
A6: 4 | BF6: 4
A7: 5 | BF7: 5
A8: 6 | BF8: 6
A9: 7 | BF9: 7
Z11: Date: | AD11: =INDEX([2]ControlPanel!$AM$4:$AO$35,MATCH($AR$11,[2]ControlPanel!$AM$4:$AM$35,0),2) -> 45432 | AF11: - | AG11: =INDEX([2]ControlPanel!$AM$4:$AO$35,MATCH($AR$11,[2]ControlPanel!$AM$4:$AM$35,0),3) -> 45427 | AO11: Phase: | AR11: Meso 1 | BH11: Planned | BN11: Actual
K13: Week 8 | Y13: Week 9 | AO13: Week 10 | BF13: Days | BH13: Ski | BI13: Mob. | BJ13: Preh | BK13: Str. | BL13: Con. | BM13: Sport | BN13: Ski | BO13: Mob. | BP13: Preh | BQ13: Str. | BR13: Con. | BS13: Sport
E14: Plyo Load | F14: Plyo Reps | K14: Elevate HR | U14: 1 | V14: 2 | W14: 3 | AI14: 1 | AJ14: 2 | AM14: 3 | AY14: 1 | AZ14: 2 | BA14: 3 | BF14: =COUNT(BF16:BF43) -> 1 | BH14: =COUNTA(BH16:BH43) -> 0 | BI14: =COUNTA(BI16:BI43) -> 0 | BJ14: =COUNTA(BJ16:BJ43) -> 0 | BK14: =COUNTA(BK16:BK43) -> 0 | BL14: =COUNTA(BL16:BL43) -> 0 | BM14: =COUNTA(BM16:BM43) -> 0 | BN14: =COUNTA(BN16:BN43) -> 0 | BO14: =COUNTA(BO16:BO43) -> 0 | ... BS14: =COUNTA(BS16:BS43) -> 0
A15: ExerciseCategory | C15: SetRepScheme | D15: 1RM | G15: %BM | H15: /side | K15: 1 | L15: Spin Bike | U15: 5 | V15: 5 | W15: 5 | Y15: 1 | Z15: Spin Bike | AI15: 5 | AJ15: 5 | AM15: 5 | AO15: 1 | AP15: Spin Bike | AY15: 5 | AZ15: 5 | BA15: 5
A16: Prehab | B16: RE | C16: Empty | D16: =IFERROR(INDEX([2]!Table1RM[#Data],MATCH($M$56,[2]!Table1RM[Athlete],0),MATCH($L16,[2]!Table1RM[#Headers],0)),"") | E16: =IF($B16="PE",INDEX([2]ExerciseInventory!$J$2:$L$276,MATCH($L16,[2]ExerciseInventory!$J$2:$J$287,0),2),"") | F16: =IF($B16="PE",INDEX([2]ExerciseInventory!$J$2:$L$276,MATCH($L16,[2]ExerciseInventory!$J$2:$J$287,0),3),"") | BF16: =$AD$11 -> 45432
A17: Prehab | B17: RE | C17: Empty | D17: =IFERROR(INDEX([2]!Table1RM[#Data],MATCH($M$56,[2]!Table1RM[Athlete],0),MATCH($L17,[2]!Table1RM[#Headers],0)),"") | E17: =IF($B17="PE",INDEX([2]ExerciseInventory!$J$2:$L$276,MATCH($L17,[2]ExerciseInventory!$J$2:$J$287,0),2),"") | F17: =IF($B17="PE",INDEX([2]ExerciseInventory!$J$2:$L$276,MATCH($L17,[2]ExerciseInventory!$J$2:$J$287,0),3),"") | K17: Movement and Mobility | U17: 1 | V17: 2 | W17: 3 | AI17: 1 | AJ17: 2 | AM17: 3 | AY17: 1 | AZ17: 2 | BA17: 3 | BF17: =IFERROR(IF(BF16+1<=$AG$11,BF16+1,NA()),"")
A18: Prehab | B18: RE | C18: Empty | D18: =IFERROR(INDEX([2]!Table1RM[#Data],MATCH($M$56,[2]!Table1RM[Athlete],0),MATCH($L18,[2]!Table1RM[#Headers],0)),"") | E18: =IF($B18="PE",INDEX([2]ExerciseInventory!$J$2:$L$276,MATCH($L18,[2]ExerciseInventory!$J$2:$J$287,0),2),"") | F18: =IF($B18="PE",INDEX([2]ExerciseInventory!$J$2:$L$276,MATCH($L18,[2]ExerciseInventory!$J$2:$J$287,0),3),"") | K18: 1 | L18: Cat Camel | U18: 6 | V18: 6 | W18: 6 | Y18: 1 | Z18: Cat Camel | AI18: 6 | AJ18: 6 | AM18: 6 | AO18: 1 | AP18: Cat Camel | AY18: 6 | AZ18: 6 | BA18: 6 | BF18: =IFERROR(IF(BF17+1<=$AG$11,BF17+1,NA()),"")
A19: Prehab | B19: RE | C19: Empty | D19: =IFERROR(INDEX([2]!Table1RM[#Data],MATCH($M$56,[2]!Table1RM[Athlete],0),MATCH($L19,[2]!Table1RM[#Headers],0)),"") | E19: =IF($B19="PE",INDEX([2]ExerciseInventory!$J$2:$L$276,MATCH($L19,[2]ExerciseInventory!$J$2:$J$287,0),2),"") | F19: =IF($B19="PE",INDEX([2]ExerciseInventory!$J$2:$L$276,MATCH($L19,[2]ExerciseInventory!$J$2:$J$287,0),3),"") | K19: 2 | L19: Side to Side Knee Rolls | U19: 8 | V19: 8 | W19: 8 | Y19: 2 | Z19: Side to Side Knee Rolls | AI19: 8 | AJ19: 8 | AM19: 8 | AO19: 2 | AP19: Side to Side Knee Rolls | AY19: 8 | AZ19: 8 | BA19: 8 | BF19: =IFERROR(IF(BF18+1<=$AG$11,BF18+1,NA()),"")
A20: Prehab | B20: RE | C20: Empty | D20: =IFERROR(INDEX([2]!Table1RM[#Data],MATCH($M$56,[2]!Table1RM[Athlete],0),MATCH($L20,[2]!Table1RM[#Headers],0)),"") | E20: =IF($B20="PE",INDEX([2]ExerciseInventory!$J$2:$L$276,MATCH($L20,[2]ExerciseInventory!$J$2:$J$287,0),2),"") | F20: =IF($B20="PE",INDEX([2]ExerciseInventory!$J$2:$L$276,MATCH($L20,[2]ExerciseInventory!$J$2:$J$287,0),3),"") | K20: 3 | L20: Heel Slides | U20: 10 | V20: 10 | W20: 10 | Y20: 3 | Z20: Heel Slides | AI20: 10 | AJ20: 10 | AM20: 10 | AO20: 3 | AP20: Heel Slides | AY20: 10 | AZ20: 10 | BA20: 10 | BF20: =IFERROR(IF(BF19+1<=$AG$11,BF19+1,NA()),"")
A21: ExerciseCategory | C21: SetRepScheme | D21: 1RM | E21: P-L | F21: P-R | G21: %BM | H21: /side | K21: 4 | L21: Leg Swings - small ROM, all directions | U21: 8 | V21: 8 | W21: 8 | Y21: 4 | Z21: Leg Swings - small ROM, all directions | AI21: 8 | AJ21: 8 | AM21: 8 | AO21: 4 | AP21: Leg Swings - small ROM, all directions | AY21: 8 | AZ21: 8 | BA21: 8 | BF21: =IFERROR(IF(BF20+1<=$AG$11,BF20+1,NA()),"")
A22: Prehab | B22: RE | C22: Empty | D22: =IFERROR(INDEX([2]!Table1RM[#Data],MATCH($M$56,[2]!Table1RM[Athlete],0),MATCH($L22,[2]!Table1RM[#Headers],0)),"") | E22: =IF($B22="PE",INDEX([2]ExerciseInventory!$J$2:$L$276,MATCH($L22,[2]ExerciseInventory!$J$2:$J$287,0),2),"") | F22: =IF($B22="PE",INDEX([2]ExerciseInventory!$J$2:$L$276,MATCH($L22,[2]ExerciseInventory!$J$2:$J$287,0),3),"") | K22: 5 | L22: Air Squat | U22: 8 | V22: 8 | W22: 8 | Y22: 5 | Z22: Air Squat w/ dowel | AI22: 8 | AJ22: 8 | AM22: 8 | AO22: 5 | AP22: Air Squat w/ dowel | AY22: 8 | AZ22: 8 | BA22: 8 | BF22: =IFERROR(IF(BF21+1<=$AG$11,BF21+1,NA()),"")
A23: Prehab | B23: RE | C23: Empty | D23: =IFERROR(INDEX([2]!Table1RM[#Data],MATCH($M$56,[2]!Table1RM[Athlete],0),MATCH($L23,[2]!Table1RM[#Headers],0)),"") | E23: =IF($B23="PE",INDEX([2]ExerciseInventory!$J$2:$L$276,MATCH($L23,[2]ExerciseInventory!$J$2:$J$287,0),2),"") | F23: =IF($B23="PE",INDEX([2]ExerciseInventory!$J$2:$L$276,MATCH($L23,[2]ExerciseInventory!$J$2:$J$287,0),3),"") | K23: 6 | L23: SL RDL + Rotation w/ support | U23: 4 | V23: 4 | W23: 4 | Y23: 6 | Z23: SL RDL + Rotation w/ support | AI23: 4 | AJ23: 4 | AM23: 4 | AO23: 6 | AP23: SL RDL + Rotation w/ support | AY23: 4 | AZ23: 4 | BA23: 4 | BF23: =IFERROR(IF(BF22+1<=$AG$11,BF22+1,NA()),"")
A24: Prehab | B24: RE | C24: Empty | D24: =IFERROR(INDEX([2]!Table1RM[#Data],MATCH($M$56,[2]!Table1RM[Athlete],0),MATCH($L24,[2]!Table1RM[#Headers],0)),"") | E24: =IF($B24="PE",INDEX([2]ExerciseInventory!$J$2:$L$276,MATCH($L24,[2]ExerciseInventory!$J$2:$J$287,0),2),"") | F24: =IF($B24="PE",INDEX([2]ExerciseInventory!$J$2:$L$276,MATCH($L24,[2]ExerciseInventory!$J$2:$J$287,0),3),"") | K24: 7 | L24: Split Squats | U24: 8 | V24: 8 | W24: 8 | Y24: 7 | Z24: Split Squats | AI24: 8 | AJ24: 8 | AM24: 8 | AO24: 7 | AP24: Split Squats | AY24: 8 | AZ24: 8 | BA24: 8 | BF24: =IFERROR(IF(BF23+1<=$AG$11,BF23+1,NA()),"")
A25: Prehab | B25: RE | C25: Empty | D25: =IFERROR(INDEX([2]!Table1RM[#Data],MATCH($M$56,[2]!Table1RM[Athlete],0),MATCH($L25,[2]!Table1RM[#Headers],0)),"") | E25: =IF($B25="PE",INDEX([2]ExerciseInventory!$J$2:$L$276,MATCH($L25,[2]ExerciseInventory!$J$2:$J$287,0),2),"") | F25: =IF($B25="PE",INDEX([2]ExerciseInventory!$J$2:$L$276,MATCH($L25,[2]ExerciseInventory!$J$2:$J$287,0),3),"") | K25: 8 | L25: Alt. Hip 90-90s | U25: 8 | V25: 8 | W25: 8 | Y25: 8 | Z25: Alt. Hip 90-90s | AI25: 8 | AJ25: 8 | AM25: 8 | AO25: 8 | AP25: Alt. Hip 90-90s | AY25: 8 | AZ25: 8 | BA25: 8 | BF25: =IFERROR(IF(BF24+1<=$AG$11,BF24+1,NA()),"")
A26: Prehab | B26: RE | C26: Empty | D26: =IFERROR(INDEX([2]!Table1RM[#Data],MATCH($M$56,[2]!Table1RM[Athlete],0),MATCH($L26,[2]!Table1RM[#Headers],0)),"") | E26: =IF($B26="PE",INDEX([2]ExerciseInventory!$J$2:$L$276,MATCH($L26,[2]ExerciseInventory!$J$2:$J$287,0),2),"") | F26: =IF($B26="PE",INDEX([2]ExerciseInventory!$J$2:$L$276,MATCH($L26,[2]ExerciseInventory!$J$2:$J$287,0),3),"") | K26: 9 | L26: Kneeling Sit Back on Heels (:05 ISO) | U26: 6 | V26: 6 | W26: 6 | Y26: 9 | Z26: Kneeling Sit Back on Heels (:05 ISO) | AI26: 6 | AJ26: 6 | AM26: 6 | AO26: 9 | AP26: Kneeling Sit Back on Heels (:05 ISO) | AY26: 6 | AZ26: 6 | BA26: 6 | BF26: =IFERROR(IF(BF25+1<=$AG$11,BF25+1,NA()),"")
A27: Prehab | B27: RE | C27: Empty | D27: =IFERROR(INDEX([2]!Table1RM[#Data],MATCH($M$56,[2]!Table1RM[Athlete],0),MATCH($L27,[2]!Table1RM[#Headers],0)),"") | E27: =IF($B27="PE",INDEX([2]ExerciseInventory!$J$2:$L$276,MATCH($L27,[2]ExerciseInventory!$J$2:$J$287,0),2),"") | F27: =IF($B27="PE",INDEX([2]ExerciseInventory!$J$2:$L$276,MATCH($L27,[2]ExerciseInventory!$J$2:$J$287,0),3),"") | BF27: =IFERROR(IF(BF26+1<=$AG$11,BF26+1,NA()),"")
A28: Prehab | B28: RE | C28: Empty | D28: =IFERROR(INDEX([2]!Table1RM[#Data],MATCH($M$56,[2]!Table1RM[Athlete],0),MATCH($L28,[2]!Table1RM[#Headers],0)),"") | E28: =IF($B28="PE",INDEX([2]ExerciseInventory!$J$2:$L$276,MATCH($L28,[2]ExerciseInventory!$J$2:$J$287,0),2),"") | F28: =IF($B28="PE",INDEX([2]ExerciseInventory!$J$2:$L$276,MATCH($L28,[2]ExerciseInventory!$J$2:$J$287,0),3),"") | K28: Activation | U28: 2x | V28: 2x | W28: 2x | AI28: 2x | AJ28: 2x | AM28: 2x | AY28: 2x | AZ28: 2x | BA28: 2x | BF28: =IFERROR(IF(BF27+1<=$AG$11,BF27+1,NA()),"")
A29: Prehab | B29: RE | C29: Empty | D29: =IFERROR(INDEX([2]!Table1RM[#Data],MATCH($M$56,[2]!Table1RM[Athlete],0),MATCH($L29,[2]!Table1RM[#Headers],0)),"") | E29: =IF($B29="PE",INDEX([2]ExerciseInventory!$J$2:$L$276,MATCH($L29,[2]ExerciseInventory!$J$2:$J$287,0),2),"") | F29: =IF($B29="PE",INDEX([2]ExerciseInventory!$J$2:$L$276,MATCH($L29,[2]ExerciseInventory!$J$2:$J$287,0),3),"") | K29: 1A | L29: Standing TKE w/ band (:05 ISO) | U29: 6 | V29: 6 | Y29: 1A | Z29: Standing TKE w/ band (:05 ISO) | AI29: 7 | AJ29: 7 | AO29: 1A | AP29: ISO SL Extension - Test Hold & Push | AY29: 2x :30 | AZ29: 3x :30 | BA29: 3x :30 | BF29: =IFERROR(IF(BF28+1<=$AG$11,BF28+1,NA()),"")
A30: Prehab | B30: RE | C30: Empty | D30: =IFERROR(INDEX([2]!Table1RM[#Data],MATCH($M$56,[2]!Table1RM[Athlete],0),MATCH($L30,[2]!Table1RM[#Headers],0)),"") | E30: =IF($B30="PE",INDEX([2]ExerciseInventory!$J$2:$L$276,MATCH($L30,[2]ExerciseInventory!$J$2:$J$287,0),2),"") | F30: =IF($B30="PE",INDEX([2]ExerciseInventory!$J$2:$L$276,MATCH($L30,[2]ExerciseInventory!$J$2:$J$287,0),3),"") | K30: 1B | L30: Low Lateral Monster Walks w/ mini band | U30: 10 | V30: 10 | Y30: 1B | Z30: Standing Hip Flexion - Green mb (:01 ISO) | AI30: 7 | AJ30: 7 | AO30: 1B | AP30: Standing Hip Flexion - Green mb - MB OH :01 ISO | AY30: 6 | AZ30: 7 | BF30: =IFERROR(IF(BF29+1<=$AG$11,BF29+1,NA()),"")
A31: Prehab | B31: RE | C31: Empty | D31: =IFERROR(INDEX([2]!Table1RM[#Data],MATCH($M$56,[2]!Table1RM[Athlete],0),MATCH($L31,[2]!Table1RM[#Headers],0)),"") | E31: =IF($B31="PE",INDEX([2]ExerciseInventory!$J$2:$L$276,MATCH($L31,[2]ExerciseInventory!$J$2:$J$287,0),2),"") | F31: =IF($B31="PE",INDEX([2]ExerciseInventory!$J$2:$L$276,MATCH($L31,[2]ExerciseInventory!$J$2:$J$287,0),3),"") | K31: 1C | L31: Standing Hip Flexion - Yellow mb (:01 ISO) | U31: 6 | V31: 6 | Y31: 1C | Z31: Backwards Treadmill Walking | AI31: 0.125 | AJ31: 0.125 | AO31: 1C | AP31: Backwards Treadmill Walking | AY31: 0.125 | AZ31: 0.125 | BF31: =IFERROR(IF(BF30+1<=$AG$11,BF30+1,NA()),"")
A32: ExerciseCategory | C32: SetRepScheme | D32: 1RM | E32: P-L | F32: P-R | G32: %BM | H32: /side | K32: 2A | L32: SL 3-way Step Down, 2 blocks | U32: 4 | W32: 4 | Y32: 2A | Z32: SL 3-way Step Down, 2-3 blocks, red band | AI32: 4 | AM32: 4 | AO32: 2A | AP32: SL 3-way Step Down, 2-3 blocks, red band | AY32: 5 | BA32: 5 | BF32: =IFERROR(IF(BF31+1<=$AG$11,BF31+1,NA()),"")
K33: 2B | L33: Lateral MH Step Overs | U33: 8/s | W33: 8 | Y33: 2B | Z33: Lateral MH Step Overs | AI33: 10/s | AM33: 10 | AO33: 2B | AP33: Lateral MH Step Over/Under | AY33: 6e/s | BA33: 6 | BF33: =IFERROR(IF(BF32+1<=$AG$11,BF32+1,NA()),"")
A34: Prehab | B34: RE | C34: Empty | D34: =IFERROR(INDEX([2]!Table1RM[#Data],MATCH($M$56,[2]!Table1RM[Athlete],0),MATCH($L34,[2]!Table1RM[#Headers],0)),"") | E34: =IF($B34="PE",INDEX([2]ExerciseInventory!$J$2:$L$276,MATCH($L34,[2]ExerciseInventory!$J$2:$J$287,0),2),"") | F34: =IF($B34="PE",INDEX([2]ExerciseInventory!$J$2:$L$276,MATCH($L34,[2]ExerciseInventory!$J$2:$J$287,0),3),"") | K34: 2C | L34: Bird Dog Leg Extensions (:02 ISO) | U34: 6 | W34: 6 | Y34: 2C | Z34: Bird Dog Leg Extensions (:02 ISO) | AI34: 8/s | AM34: 8 | AO34: 2C | AP34: Bird Dogs (Arm & Leg) (:02 ISO) | AY34: 6/s | BA34: 6 | BF34: =IFERROR(IF(BF33+1<=$AG$11,BF33+1,NA()),"")
K35: 3A | L35: SL Wall Sit (:10 ISO) | V35: 3 | W35: 3 | Y35: 3A | Z35: SL Wall Sit (:15 ISO) | AJ35: 2/s | AM35: 2 | AO35: 3A | AP35: SL Decline Wall Sit (:15 ISO) - 90deg? | AZ35: 2/s | BA35: 2 | BF35: =IFERROR(IF(BF34+1<=$AG$11,BF34+1,NA()),"")
A36: Prehab | B36: RE | C36: Empty | D36: =IFERROR(INDEX([2]!Table1RM[#Data],MATCH($M$56,[2]!Table1RM[Athlete],0),MATCH($L36,[2]!Table1RM[#Headers],0)),"") | E36: =IF($B36="PE",INDEX([2]ExerciseInventory!$J$2:$L$276,MATCH($L36,[2]ExerciseInventory!$J$2:$J$287,0),2),"") | F36: =IF($B36="PE",INDEX([2]ExerciseInventory!$J$2:$L$276,MATCH($L36,[2]ExerciseInventory!$J$2:$J$287,0),3),"") | K36: 3B | L36: Standing Hip ADD w/ cable | V36: 10 | W36: 10 | Y36: 3B | Z36: Knee Side Plank + Clamshell | AJ36: 8/s | AM36: 8 | AO36: 3B | AP36: Knee Side Plank + opp Straight Leg Raise | AZ36: 8/s | BA36: 8 | BF36: =IFERROR(IF(BF35+1<=$AG$11,BF35+1,NA()),"")
K37: 3C | L37: Alt. Dead Bug Leg Ext. w/ OH band | V37: 8 | W37: 8 | Y37: 3C | Z37: Alt. Dead Bug Leg Ext. w/ OH band | AJ37: 10/s | AM37: 10 | AO37: 3C | AP37: Alt. Dead Bug Leg Ext. w/ OH band | AZ37: 10/s | BA37: 10 | BF37: =IFERROR(IF(BF36+1<=$AG$11,BF36+1,NA()),"")
A38: Prehab | B38: RE | C38: Empty | D38: =IFERROR(INDEX([2]!Table1RM[#Data],MATCH($M$56,[2]!Table1RM[Athlete],0),MATCH($L38,[2]!Table1RM[#Headers],0)),"") | E38: =IF($B38="PE",INDEX([2]ExerciseInventory!$J$2:$L$276,MATCH($L38,[2]ExerciseInventory!$J$2:$J$287,0),2),"") | F38: =IF($B38="PE",INDEX([2]ExerciseInventory!$J$2:$L$276,MATCH($L38,[2]ExerciseInventory!$J$2:$J$287,0),3),"") | BF38: =IFERROR(IF(BF37+1<=$AG$11,BF37+1,NA()),"")
K39: Balance and Proprioception | U39: 2x | V39: 2x | W39: 2x | AI39: 2x | AJ39: 2x | AM39: 2x | AY39: 2x | AZ39: 2x | BA39: 2x | BF39: =IFERROR(IF(BF38+1<=$AG$11,BF38+1,NA()),"")
A40: Prehab | B40: RE | C40: Empty | D40: =IFERROR(INDEX([2]!Table1RM[#Data],MATCH($M$56,[2]!Table1RM[Athlete],0),MATCH($L40,[2]!Table1RM[#Headers],0)),"") | E40: =IF($B40="PE",INDEX([2]ExerciseInventory!$J$2:$L$276,MATCH($L40,[2]ExerciseInventory!$J$2:$J$287,0),2),"") | F40: =IF($B40="PE",INDEX([2]ExerciseInventory!$J$2:$L$276,MATCH($L40,[2]ExerciseInventory!$J$2:$J$287,0),3),"") | K40: 1A | L40: DL Squats - Bosu (flat up) | U40: 8 | W40: 8 | Y40: 1A | Z40: Square Balance Board L-R | AI40: :30 | AM40: :30 | AO40: 1 | AP40: ISO Decline Squat + Lateral Reaches | AY40: :30 | AZ40: :30 | BF40: =IFERROR(IF(BF39+1<=$AG$11,BF39+1,NA()),"")
K41: 1B | L41: Active SL Balance | U41: :30 | W41: :30 | Y41: 1B | Z41: DL Squats - Bosu (flat up) - plate | AI41: 8 | AM41: 8 | AO41: 2 | AP41: Alt. MB Rot. Pass- BOSU - Facing Wall | AY41: 8/s | BA41: 8 | BF41: =IFERROR(IF(BF40+1<=$AG$11,BF40+1,NA()),"")
A42: Prehab | B42: RE | C42: Empty | D42: =IFERROR(INDEX([2]!Table1RM[#Data],MATCH($M$56,[2]!Table1RM[Athlete],0),MATCH($L42,[2]!Table1RM[#Headers],0)),"") | E42: =IF($B42="PE",INDEX([2]ExerciseInventory!$J$2:$L$276,MATCH($L42,[2]ExerciseInventory!$J$2:$J$287,0),2),"") | F42: =IF($B42="PE",INDEX([2]ExerciseInventory!$J$2:$L$276,MATCH($L42,[2]ExerciseInventory!$J$2:$J$287,0),3),"") | K42: 1C | L42: ISO Lunge + Eyes Closed | U42: :20 | W42: :20 | Y42: 1C | Z42: Active SL Balance - eyes closed | AI42: :20 | AM42: :20 | AO42: 3 | AP42: DL Half Squats - Balance Board | AY42: 8 | AZ42: 8 | BA42: 8 | BF42: =IFERROR(IF(BF41+1<=$AG$11,BF41+1,NA()),"")
AO43: 4 | AP43: Active SL Balance - eyes closed | AZ43: :30 | BA43: :30 | BF43: =IFERROR(IF(BF42+1<=$AG$11,BF42+1,NA()),"")
...
